Workbook
Name LSL: [1]names!$B$12:$B$13
Name paylevel: [1]Sheet1!$A$1:$A$240
Name super: [1]names!$B$6:$B$8
Name type: #REF!

Sheet 1. Salary Scales
B1: Salary Scales for ARC Discovery Projects commencing in 2027 (DP27) | I1: PhD Stipend (See: Note 5)
C2: Increment Level (See: Note 3) | D2: Forecast 2027 hourly casual rates (inc. 30% oncosts) | E2: Forecast 2027 yearly salaries (ex. oncosts) (See: Note 1) | F2: Forecast 2027 yearly salaries (inc. 30% oncosts) (See: Note 1) | I2: Year | J2: Rate to request from ARC | K2: UoM top up rate for stipends requested from ARC | L2: Total Stipend / Rate to enter for stipends fully funded by UoM
I3: Year 1 /2027 | J3: 34338 | K3: 6347 | L3: 40685
B4: Academic and Research Staff | I4: Year 2 /2028 | J4: 34338 | K4: 7567.55 | L4: 41905.55
B5: Grade 1 (Research Assistant) (Bachelors Entry Point) | C5: 1 | D5: 72 | E5: 84530 | F5: 109889 | I5: Year 3 /2029 | J5: 34338 | K5: 8824.7165 | L5: 43162.717
C6: 2 | D6: 74 | E6: 87285 | F6: 113471 | I6: Year 4 /2030 | J6: 34338 | K6: 10119.598 | L6: 44457.598
C7: 3 | D7: 79 | E7: 92581 | F7: 120355 | I7: Year 5 /2031 | J7: 34338 | K7: 11453.326 | L7: 45791.326
B8: Grade 2 / Academic Level A (Research Assistant/ Research Associate) | C8: A.1 | D8: 79 | E8: 92581 | F8: 120355
C9: A.2 | D9: 83 | E9: 97860 | F9: 127219
C10: A.3 | D10: 88 | E10: 103155 | F10: 134102
C11: A.4 | D11: 92 | E11: 108443 | F11: 140977
C12: A.5 | D12: 96 | E12: 112745 | F12: 146569
B13: PhD Entry Point | C13: A.6 | D13: 99 | E13: 117038 | F13: 152149
C14: A.7 | D14: 103 | E14: 121331 | F14: 157731
C15: A.8 | D15: 107 | E15: 125627 | F15: 163316
B16: Academic Level B (Senior Research Associate) | C16: B.1 | D16: 112 | E16: 132248 | F16: 171923
C17: B.2 | D17: 116 | E17: 137203 | F17: 178364
C18: B.3 | D18: 121 | E18: 142161 | F18: 184810
C19: B.4 | D19: 125 | E19: 147118 | F19: 191254
C20: B.5 | D20: 129 | E20: 152082 | F20: 197707
C21: B.6 | D21: 133 | E21: 157038 | F21: 204150
B22: Academic Level C (Senior Research Associate) | C22: C.1 | D22: 137 | E22: 161994 | F22: 210593
C23: C.2 | D23: 142 | E23: 166963 | F23: 217053
C24: C.3 | D24: 146 | E24: 171914 | F24: 223489
C25: C.4 | D25: 150 | E25: 176866 | F25: 229926
C26: C.5 | D26: 154 | E26: 181823 | F26: 236370
C27: C.6 | D27: 158 | E27: 186788 | F27: 242824
B28: Academic Level D (Associate Professor) | C28: D.1 | D28: 165 | E28: 195056 | F28: 253573
C29: D.2 | D29: 171 | E29: 201665 | F29: 262164
C30: D.3 | D30: 176 | E30: 208271 | F30: 270753
C31: D.4 | D31: 182 | E31: 214891 | F31: 279359
B32: Academic Level E (Professor) | C32: E.1 | D32: 213 | E32: 251246 | F32: 326621
B34: General and Technical Assistance/Professional Staff
B35: Higher Education Worker Grade 3 | C35: HEW 3.1 | D35: 63 | E35: 73790 | F35: 95927
C36: HEW 3.2 | D36: 64 | E36: 75269 | F36: 97850
C37: HEW 3.3 | D37: 65 | E37: 76769 | F37: 99800
C38: HEW 3.4 | D38: 67 | E38: 78305 | F38: 101797
C39: HEW 3.5 | D39: 68 | E39: 79875 | F39: 103839
C40: HEW 3.6 | D40: 69 | E40: 81472 | F40: 105914
B41: Higher Education Worker Grade 4 | C41: HEW 4.1 | D41: 73 | E41: 85297 | F41: 110886
...

Sheet 2. DP27 Budget Tool
A1: DP25 Detailed Budget Template
A2: TOTAL PERSONNEL (ARC) | B2: =SUM(C14,J14,Q14,X14,AE14)
A3: TOTAL TEACHING RELIEF (ARC) | B3: =SUM(C35,J35,Q35,X35,AE35)
A4: TOTAL TRAVEL (ARC) | B4: =SUM(C46,J46,Q46,X46,AE46)
A5: TOTAL FIELD RESEARCH (ARC) | B5: =SUM(C66,J66,Q66,X66, AE66)
A6: TOTAL EQUIPMENT (ARC) | B6: =SUM(C87,J87,Q87,X87,AE87)
A7: TOTAL MAINTENANCE (ARC) | B7: =SUM(C108,J108,Q108,X108,AE108)
A8: TOTAL OTHER (ARC) | B8: =SUM(C129,J129,Q129,X129,AE129)
A9: TOTAL REQUESTED ARC FUNDING | B9: =SUM(B2:B8) | C9: YEAR 1 BUDGET (2027) | J9: YEAR 2 BUDGET (2028) | Q9: YEAR 3 BUDGET (2029) | X9: YEAR 4 BUDGET (2030) | AE9: YEAR 5 BUDGET (2031)
A10: Description | C10: ARC | D10: Admin Org | F10: Other Eligible Org | H10: Other Org | J10: ARC | K10: Admin Org | M10: Other Eligible Org | O10: Other Org | Q10: ARC | R10: Admin Org | T10: Other Eligible Org | V10: Other Org | X10: ARC | Y10: Admin Org | AA10: Other Eligible Org | AC10: Other Org | AE10: ARC | AF10: Admin Org | AH10: Other Eligible Org | AJ10: Other Org
C11: Cash | D11: Cash | E11: In-Kind | F11: Cash | G11: In-Kind | H11: Cash | I11: In-Kind | J11: Cash | K11: Cash | L11: In-Kind | M11: Cash | N11: In-Kind | O11: Cash | P11: In-Kind | Q11: Cash | R11: Cash | S11: In-Kind | T11: Cash | U11: In-Kind | V11: Cash | W11: In-Kind | X11: Cash | Y11: Cash | Z11: In-Kind | AA11: Cash | AB11: In-Kind | AC11: Cash | AD11: In-Kind | AE11: Cash | AF11: Cash | AG11: In-Kind | AH11: Cash | AI11: In-Kind | AJ11: Cash | AK11: In-Kind
A12: PROJECT TOTAL | C12: =SUM(C14,C35,C46,C66,C87,C108,C129) | D12: =SUM(D14,D35,D46,D66,D87,D108,D129) | E12: =SUM(E14,E35,E46,E66,E87,E108,E129) | F12: =SUM(F14,F35,F46,F66,F87,F108,F129) | G12: =SUM(G14,G35,G46,G66,G87,G108,G129) | H12: =SUM(H14,H35,H46,H66,H87,H108,H129) | I12: =SUM(I14,I35,I46,I66,I87,I108,I129) | J12: =SUM(J14,J35,J46,J66,J87,J108,J129) | ... AK12: =SUM(AK14,AK35,AK46,AK66,AK87,AK108,AK129)
A13: Remaining project funding that can be requested from ARC | C13: =500000-SUM(C14,C35,C46,C66,C87,C108,C129) | J13: =500000-SUM(J14,J35,J46,J66,J87,J108,J129) | Q13: =500000-SUM(Q14,Q35,Q46,Q66,Q87,Q108,Q129) | X13: =500000-SUM(X14,X35,X46,X66,X87,X108,X129) | AE13: =500000-SUM(AE14,AE35,AE46,AE66,AE87,AE108,AE129)
A14: PERSONNEL | C14: =SUM(C15:C34) | D14: =SUM(D15:D34) | E14: =SUM(E15:E34) | F14: =SUM(F15:F34) | G14: =SUM(G15:G34) | H14: =SUM(H15:H34) | I14: =SUM(I15:I34) | J14: =SUM(J15:J34) | ... AK14: =SUM(AK15:AK34)
A15: CI Xingliang Yuan, Level D.4 at 0.2 FTE (plus on-costs) | C15: 0 | D15: 0 | E15: 8339 | J15: 0 | K15: 0 | L15: 8339 | Q15: 0 | R15: 0 | S15: 43989 | X15: 0 | Y15: 0 | Z15: 0 | AE15: 0 | AF15: 0 | AG15: 0
A16: CI Shaanan Cohney, Level C.3 at 0.2 FTE (plus on-costs) | C16: 0 | D16: 0 | E16: 18751 | J16: 0 | K16: 0 | L16: 20038 | Q16: 0 | R16: 0 | S16: 21327 | X16: 0 | Y16: 0 | Z16: 0 | AE16: 0 | AF16: 0 | AG16: 0
A17: CI Shangqi Lai, Level B.3 at 0.2 FTE (plus on-costs) | C17: 0 | D17: 0 | E17: 36962 | J17: 0 | K17: 0 | L17: 38251 | Q17: 0 | R17: 0 | S17: 39541 | X17: 0 | Y17: 0 | Z17: 0 | AE17: 0 | AF17: 0 | AG17: 0
A18: HDR (Higher Degree by Research stipend) | C18: 0 | D18: 0 | E18: 6288 | J18: 0 | K18: 0 | L18: 7388 | Q18: 0 | R18: 0 | S18: 7388 | X18: 0 | Y18: 0 | Z18: 0 | AE18: 0 | AF18: 0 | AG18: 0
A19: HDR (Higher Degree by Research stipend, ARC funded) ARC funding is requested for the HDR candidate to support multimodal prompt-auditing implementation, robustness evaluation, benchmarking, and experimental analysis across the project. The University of Melbourne will provide the associated stipend top-up from non-ARC funds. | C19: 38500 | D19: 0 | E19: 0 | J19: 39600 | K19: 0 | L19: 0 | Q19: 39600 | R19: 0 | S19: 0 | X19: 0 | Y19: 0 | Z19: 0 | AE19: 0 | AF19: 0 | AG19: 0
A20: Postdoctoral Research Associate (B.1-B.3) | C20: 171923 | D20: 0 | E20: 0 | J20: 178364 | K20: 0 | L20: 0 | Q20: 184810 | R20: 0 | S20: 0 | X20: 0 | Y20: 0 | Z20: 0 | AE20: 0 | AF20: 0 | AG20: 0
A35: TEACHING RELIEF | C35: =SUM(C36:C45) | D35: =SUM(D36:D45) | E35: =SUM(E36:E45) | F35: =SUM(F36:F45) | G35: =SUM(G36:G45) | H35: =SUM(H36:H45) | I35: =SUM(I36:I45) | J35: =SUM(J36:J45) | ... AK35: =SUM(AK36:AK45)
A46: TRAVEL | C46: =SUM(C47:C65) | D46: =SUM(D47:D65) | E46: =SUM(E47:E65) | F46: =SUM(F47:F65) | G46: =SUM(G47:G65) | H46: =SUM(H47:H65) | I46: =SUM(I47:I65) | J46: =SUM(J47:J65) | ... AK46: =SUM(AK47:AK65)
A48: Year 1 US security conference travel for CI + HDR Budget covers return economy airfares for two travellers ($8,150), six nights of accommodation near the venue ($4,000), two conference registrations ($2,700), and local transport and incidentals ($1,370). | C48: 16220 | D48: 0 | E48: 0 | J48: 0 | K48: 0 | L48: 0 | Q48: 0 | R48: 0 | S48: 0 | X48: 0 | Y48: 0 | Z48: 0 | AE48: 0 | AF48: 0 | AG48: 0
A49: Year 2 US security conference travel for CI + HDR Budget covers return economy airfares for two travellers ($8,250), six nights of accommodation near the venue ($4,050), two conference registrations ($2,850), and local transport and incidentals ($1,390). | C49: 0 | D49: 0 | E49: 0 | J49: 16540 | K49: 0 | L49: 0 | Q49: 0 | R49: 0 | S49: 0 | X49: 0 | Y49: 0 | Z49: 0 | AE49: 0 | AF49: 0 | AG49: 0
A50: Year 3 US security conference travel for CI + HDR Budget covers return economy airfares for two travellers ($8,450), six nights of accommodation near the venue ($4,150), two conference registrations ($2,950), and local transport and incidentals ($1,432). | C50: 0 | D50: 0 | E50: 0 | J50: 0 | K50: 0 | L50: 0 | Q50: 16982 | R50: 0 | S50: 0 | X50: 0 | Y50: 0 | Z50: 0 | AE50: 0 | AF50: 0 | AG50: 0
A66: FIELD RESEARCH | C66: =SUM(C67:C86) | D66: =SUM(D67:D86) | E66: =SUM(E67:E86) | F66: =SUM(F67:F86) | G66: =SUM(G67:G86) | H66: =SUM(H67:H86) | I66: =SUM(I67:I86) | J66: =SUM(J67:J86) | ... AK66: =SUM(AK67:AK86)
A87: EQUIPMENT | C87: =SUM(C88:C107) | D87: =SUM(D88:D107) | E87: =SUM(E88:E107) | F87: =SUM(F88:F107) | G87: =SUM(G88:G107) | H87: =SUM(H88:H107) | I87: =SUM(I88:I107) | J87: =SUM(J88:J107) | ... AK87: =SUM(AK88:AK107)
A108: MAINTENANCE | C108: =SUM(C109:C128) | D108: =SUM(D109:D128) | E108: =SUM(E109:E128) | F108: =SUM(F109:F128) | G108: =SUM(G109:G128) | H108: =SUM(H109:H128) | I108: =SUM(I109:I128) | J108: =SUM(J109:J128) | ... AK108: =SUM(AK109:AK128)
A129: OTHER | C129: =SUM(C130:C149) | D129: =SUM(D130:D149) | E129: =SUM(E130:E149) | F129: =SUM(F130:F149) | G129: =SUM(G130:G149) | H129: =SUM(H130:H149) | I129: =SUM(I130:I149) | J129: =SUM(J130:J149) | ... AK129: =SUM(AK130:AK149)
A130: Publication Fees for Gold Open Access | C130: 4000 | D130: 0 | E130: 0 | J130: 4000 | K130: 0 | L130: 0 | Q130: 8000 | R130: 0 | S130: 0 | X130: 0 | Y130: 0 | Z130: 0 | AE130: 0 | AF130: 0 | AG130: 0
A131: Industry dissemination workshop with Australian organisations and partners End-of-project workshop to present the prototype, evaluation results, and practical guidance for privacy-preserving AI auditing to Australian industry and public-sector organisations. Budget covers venue and hybrid delivery support, workshop catering, materials, and event support. | Q131: 4000
A132: Postdoctoral researcher laptop and setup University in-kind support for one project laptop and standard setup for the postdoctoral researcher at project commencement, to support secure development, experimental evaluation, code management, and prototype work across RT1--RT3. | E132: 3000
A133: HDR candidate laptop and setup University in-kind support for one project laptop and standard setup for the HDR candidate at project commencement, to support implementation, benchmarking, reproducibility studies, and writing across RT1--RT3. | E133: 3000
A134: FEIT HDR conference-travel support for domestic dissemination University cash support of up to $2,000 through the standard FEIT Conference Travel Grant for one domestic HDR dissemination trip in Year 2 to present accepted work at a relevant conference or workshop hosted by a peer Australian university. | K134: 2000

Sheet 3. DP27 One-Line Budget Example
A1: DP27 Example Budget For Reference ONLY
A2: TOTAL PERSONNEL (ARC) | B2: =SUM(C14,J14,Q14)
A3: TOTAL TEACHING RELIEF (ARC) | B3: =SUM(C21,J21,Q21)
A4: TOTAL TRAVEL (ARC) | B4: =SUM(C24,J24,Q24)
A5: TOTAL FIELD RESEARCH (ARC) | B5: =SUM(C26,J26,Q26)
A6: TOTAL EQUIPMENT (ARC) | B6: =SUM(C28,J28,Q28)
A7: TOTAL MAINTENANCE (ARC) | B7: =SUM(C30,J30,Q30)
A8: TOTAL OTHER (ARC) | B8: =SUM(C32,J32,Q32)
A9: TOTAL REQUESTED ARC FUNDING | B9: =SUM(B2:B8) | C9: YEAR 1 BUDGET (2027) | J9: YEAR 2 BUDGET (2028) | Q9: YEAR 3 BUDGET (2029)
A10: Description | C10: ARC | D10: Admin Org | F10: Other Eligible Org | H10: Other Org | J10: ARC | K10: Admin Org | M10: Other Eligible Org | O10: Other Org | Q10: ARC | R10: Admin Org | T10: Other Eligible Org | V10: Other Org
C11: Cash | D11: Cash | E11: In-Kind | F11: Cash | G11: In-Kind | H11: Cash | I11: In-Kind | J11: Cash | K11: Cash | L11: In-Kind | M11: Cash | N11: In-Kind | O11: Cash | P11: In-Kind | Q11: Cash | R11: Cash | S11: In-Kind | T11: Cash | U11: In-Kind | V11: Cash | W11: In-Kind
A12: PROJECT TOTAL | C12: =SUM(C14,C21,C24,C26,C28,C30,C32) | D12: =SUM(D14,D21,D24,D26,D28,D30,D32) | E12: =SUM(E14,E21,E24,E26,E28,E30,E32) | F12: =SUM(F14,F21,F24,F26,F28,F30,F32) | G12: =SUM(G14,G21,G24,G26,G28,G30,G32) | H12: =SUM(H14,H21,H24,H26,H28,H30,H32) | I12: =SUM(I14,I21,I24,I26,I28,I30,I32) | J12: =SUM(J14,J21,J24,J26,J28,J30,J32) | ... W12: =SUM(W14,W21,W24,W26,W28,W30,W32)
A13: Remaining project funding that can be requested from ARC | C13: =500000-C12 | J13: =500000-J12 | Q13: =500000-Q12
A14: PERSONNEL | C14: =SUM(C15:C20) | D14: =SUM(D15:D20) | E14: =SUM(E15:E20) | F14: =SUM(F15:F20) | G14: =SUM(G15:G20) | H14: =SUM(H15:H20) | I14: =SUM(I15:I20) | J14: =SUM(J15:J20) | ... W14: =SUM(W15:W20)
A15: CI Smith, 0.5FTE, Level D1-D3 | E15: =+'1. Salary Scales'!F28*0.5 | L15: =+'1. Salary Scales'!F29*0.5 | S15: =+'1. Salary Scales'!F30*0.5
A16: CI Lee, 0.2FTE, Level B5-B6 | G16: =+'1. Salary Scales'!F26*0.2 | N16: =+'1. Salary Scales'!F21*0.2 | U16: =+'1. Salary Scales'!F21*0.2
A17: PI Nguyen, 0.1FTE, Level E | I17: =+'1. Salary Scales'!F32*0.1 | P17: =+'1. Salary Scales'!F32*0.1 | W17: =+'1. Salary Scales'!F32*0.1
A18: HDR (Higher Degree by Research Stipend) | C18: =+'1. Salary Scales'!J3 | D18: =+'1. Salary Scales'!K3 | J18: =+'1. Salary Scales'!J4 | K18: =+'1. Salary Scales'!K4 | Q18: =+'1. Salary Scales'!J5 | R18: =+'1. Salary Scales'!K5
A19: HDR (Higher Degree by Research Stipend) - UoM funded | D19: =+'1. Salary Scales'!L3 | K19: =+'1. Salary Scales'!L4 | R19: =+'1. Salary Scales'!L5
A20: Research Associate, Level A7-A8, 1.0FTE | C20: =+'1. Salary Scales'!F14 | J20: =+'1. Salary Scales'!F15 | Q20: =+'1. Salary Scales'!F15
A21: TEACHING RELIEF | C21: =SUM(C22:C23) | D21: =SUM(D22:D23) | E21: =SUM(E22:E23) | F21: =SUM(F22:F23) | G21: =SUM(G22:G23) | H21: =SUM(H22:H23) | I21: =SUM(I22:I23) | J21: =SUM(J22:J23) | ... W21: =SUM(W22:W23)
A22: Teaching Relief for A/Prof Smith | C22: 25000 | J22: 25000
A23: Teaching Relief for Dr Lee | C23: 0 | J23: 0 | Q23: 15000
A24: TRAVEL | C24: =SUM(C25:C25) | D24: =SUM(D25:D25) | E24: =SUM(E25:E25) | F24: =SUM(F25:F25) | G24: =SUM(G25:G25) | H24: =SUM(H25:H25) | I24: =SUM(I25:I25) | J24: =SUM(J25:J25) | ... W24: =SUM(W25:W25)
A25: Total Travel Costs | C25: 2500 | D25: 2500 | F25: 1000 | J25: 3240 | K25: 2500 | M25: 2500 | O25: 1000 | Q25: 10000 | R25: 2500 | T25: 1000 | V25: 2500
A26: FIELD RESEARCH | C26: =SUM(C27:C27) | D26: =SUM(D27:D27) | E26: =SUM(E27:E27) | F26: =SUM(F27:F27) | G26: =SUM(G27:G27) | H26: =SUM(H27:H27) | I26: =SUM(I27:I27) | J26: =SUM(J27:J27) | ... W26: =SUM(W27:W27)
A27: Total Field Research Costs | C27: 38600 | E27: 15000
A28: EQUIPMENT | C28: =SUM(C29:C29) | D28: =SUM(D29:D29) | E28: =SUM(E29:E29) | F28: =SUM(F29:F29) | G28: =SUM(G29:G29) | H28: =SUM(H29:H29) | I28: =SUM(I29:I29) | J28: =SUM(J29:J29) | ... W28: =SUM(W29:W29)
A29: Total Equipment Costs | C29: 20000 | E29: 42000 | G29: 12000 | I29: 5000 | J29: 10000 | L29: 42000 | N29: 12000 | P29: 5000
A30: MAINTENANCE | C30: =SUM(C31:C31) | D30: =SUM(D31:D31) | E30: =SUM(E31:E31) | F30: =SUM(F31:F31) | G30: =SUM(G31:G31) | H30: =SUM(H31:H31) | I30: =SUM(I31:I31) | J30: =SUM(J31:J31) | ... W30: =SUM(W31:W31)
A31: Total Maintenance Costs | C31: 45000 | D31: 2000 | J31: 45000 | K31: 2000 | Q31: 25000 | R31: 2000
A32: OTHER | C32: =SUM(C33:C33) | D32: =SUM(D33:D33) | E32: =SUM(E33:E33) | F32: =SUM(F33:F33) | G32: =SUM(G33:G33) | H32: =SUM(H33:H33) | I32: =SUM(I33:I33) | J32: =SUM(J33:J33) | ... W32: =SUM(W33:W33)
A33: Total Other Costs | C33: 5000 | G33: 4000 | I33: 1000 | J33: 5000 | N33: 4000 | P33: 1000 | Q33: 15000

Sheet 4. ATO Rates - Domestic
A1: Table 1: Level B.4 and below Sourced from: https://www.ato.gov.au/law/view/document?docid=TXD/TD20254/NAT/ATO/00001 | G1: Table 2: Level B.5 and above Sourced from: https://www.ato.gov.au/law/view/document?docid=TXD/TD20254/NAT/ATO/00001
A2: Place | B2: Accomm. ($) | C2: Food and drink ($) | D2: Incidentals ($) | E2: Daily total ($) | G2: Place | H2: Accomm. ($) | I2: Food and drink ($) | J2: Incidentals ($) | K2: Daily total ($)
A3: Adelaide | B3: 158 | C3: breakfast 34.75 | D3: 24.5 | E3: 323 | G3: Adelaide | H3: 211 | I3: breakfast 37.85 | J3: 35.05 | K3: 412.35
C4: lunch 39.10 | I4: lunch 53.45
C5: dinner 66.65 | I5: dinner 75.00
A6: Brisbane | B6: 181 | C6: breakfast 34.75 | D6: 24.5 | E6: 346 | G6: Brisbane | H6: 257 | I6: breakfast 37.85 | J6: 35.05 | K6: 458.35
C7: lunch 39.10 | I7: lunch 53.45
C8: dinner 66.65 | I8: dinner 75.00
A9: Canberra | B9: 178 | C9: breakfast 34.75 | D9: 24.5 | E9: 343 | G9: Canberra | H9: 246 | I9: breakfast 37.85 | J9: 35.05 | K9: 447.35
C10: lunch 39.10 | I10: lunch 53.45
C11: dinner 66.65 | I11: dinner 75.00
A12: Darwin | B12: 220 | C12: breakfast 34.75 | D12: 24.5 | E12: 385 | G12: Darwin | H12: 293 | I12: breakfast 37.85 | J12: 35.05 | K12: 494.35
C13: lunch 39.10 | I13: lunch 53.45
C14: dinner 66.65 | I14: dinner 75.00
A15: Hobart | B15: 176 | C15: breakfast 34.75 | D15: 24.5 | E15: 341 | G15: Hobart | H15: 235 | I15: breakfast 37.85 | J15: 35.05 | K15: 436.35
C16: lunch 39.10 | I16: lunch 53.45
C17: dinner 66.65 | I17: dinner 75.00
A18: Melbourne | B18: 173 | C18: breakfast 34.75 | D18: 24.5 | E18: 338 | G18: Melbourne | H18: 231 | I18: breakfast 37.85 | J18: 35.05 | K18: 432.35
C19: lunch 39.10 | I19: lunch 53.45
C20: dinner 66.65 | I20: dinner 75.00
A21: Perth | B21: 180 | C21: breakfast 34.75 | D21: 24.5 | E21: 345 | G21: Perth | H21: 245 | I21: breakfast 37.85 | J21: 35.05 | K21: 446.35
C22: lunch 39.10 | I22: lunch 53.45
C23: dinner 66.65 | I23: dinner 75.00
A24: Sydney | B24: 223 | C24: breakfast 34.75 | D24: 24.5 | E24: 388 | G24: Sydney | H24: 297 | I24: breakfast 37.85 | J24: 35.05 | K24: 498.35
C25: lunch 39.10 | I25: lunch 53.45
C26: dinner 66.65 | I26: dinner 75.00
A27: * High-cost | B27: see Table 4 at hyperlink below | C27: breakfast 34.75 | D27: 24.5 | E27: variable | G27: High-cost | H27: see Table 4 at hyperlink below | I27: breakfast 37.85 | J27: 35.05 | K27: variable
A28: country centres | C28: lunch 39.10 | G28: country centres | I28: lunch 53.45
C29: dinner 66.65 | I29: dinner 75.00
A30: Other country | B30: 141 | C30: breakfast 31.15 | D30: 24.5 | E30: 293.5 | G30: Other country | H30: 188 | I30: breakfast 37.85 | J30: 35.05 | K30: 362.35
A31: centres | C31: lunch 35.55 | G31: centres | I31: lunch 53.45
C32: dinner 61.30 | I32: dinner 75.00
A34: * High-cost country centres are in table 4 at: https://www.ato.gov.au/law/view/document?docid=TXD/TD20254/NAT/ATO/00001
A37: Travel Budget Preparation:
A38: * D1: Enter a one-line budget figure for travel costs essential to the project i.e. Total Travel Costs
A39: * D2/D3: Details and justification of ‘Travel’ and costings must be included in Questions D2 and D3 as appropriate, such as individual economy-class flights, accommodation, travel allowance, conference costs etc.
A40: * Travel costs are capped at $50,000 per project
A41: * Travel and accommodation costs related to carrying out field research or carers’ costs are not included in this $50,000 limit. Refer to subsections 5.2.e. of the Grant Guidelines for further information.

Sheet 5. ATO Rates - International
A1: Sourced from: https://www.ato.gov.au/law/view/document?docid=TXD/TD20254/NAT/ATO/00001
A2: Country | B2: Cost group | C2: Country | D2: Cost group | E2: Country | F2: Cost group | H2: Table 6 - Level B.4 and below | M2: Table 7 - Level B.5 and above
A3: Albania | B3: 2 | C3: Georgia | D3: 3 | E3: North Macedonia | F3: 2 | H3: Cost group | I3: Meals ($) | J3: Incidentals ($) | K3: Total ($) | M3: Cost group | N3: Meals ($) | O3: Incidentals ($) | P3: Total ($)
A4: Algeria | B4: 3 | C4: Germany | D4: 5 | E4: Norway | F4: 6 | H4: 1 | I4: 75 | J4: 25 | K4: 100 | M4: 1 | N4: 95 | O4: 25 | P4: 120
A5: Antigua and Barbuda | B5: 6 | C5: Gibraltar | D5: 4 | E5: Oman | F5: 6 | H5: 2 | I5: 110 | J5: 30 | K5: 140 | M5: 2 | N5: 130 | O5: 35 | P5: 165
A6: Argentina | B6: 2 | C6: Greece | D6: 4 | E6: Pakistan | F6: 2 | H6: 3 | I6: 150 | J6: 35 | K6: 185 | M6: 3 | N6: 175 | O6: 40 | P6: 215
A7: Armenia | B7: 3 | C7: Guatemala | D7: 4 | E7: Panama | F7: 4 | H7: 4 | I7: 195 | J7: 35 | K7: 230 | M7: 4 | N7: 215 | O7: 45 | P7: 260
A8: Austria | B8: 5 | C8: Guyana | D8: 4 | E8: Papua New Guinea | F8: 4 | H8: 5 | I8: 235 | J8: 40 | K8: 275 | M8: 5 | N8: 290 | O8: 50 | P8: 340
A9: Azerbaijan | B9: 3 | C9: Hong Kong | D9: 6 | E9: Paraguay | F9: 2 | H9: 6 | I9: 280 | J9: 45 | K9: 325 | M9: 6 | N9: 360 | O9: 50 | P9: 410
A10: Bahamas | B10: 6 | C10: Hungary | D10: 3 | E10: Peru | F10: 4
A11: Bahrain | B11: 6 | C11: Iceland | D11: 6 | E11: Philippines | F11: 4
A12: Bangladesh | B12: 4 | C12: India | D12: 3 | E12: Poland | F12: 3 | H12: International Accommodation:
A13: Barbados | B13: 6 | C13: Indonesia | D13: 3 | E13: Portugal | F13: 4 | H13: ATO guidelines for international travel only specify costs of meals and incidentals. To estimate accommodation costs for locations you are unfamiliar with, search Expedia.com and use the average cost for a 3* or 4* hotel (depending on the location).
A14: Belarus | B14: 2 | C14: Iran | D14: 1 | E14: Puerto Rico | F14: 6
A15: Belgium | B15: 5 | C15: Iraq | D15: 4 | E15: Qatar | F15: 6
A16: Bermuda | B16: 6 | C16: Ireland | D16: 6 | E16: Romania | F16: 3
A17: Bolivia | B17: 3 | C17: Israel | D17: 6 | E17: Russia | F17: 4 | H17: For research trips (not conferences), you may be able to use academic guesthouses or colleges which are considerably cheaper than hotels. For longer stays, furnished appartments can also be a cheaper alternative.
A18: Bosnia | B18: 2 | C18: Italy | D18: 5 | E18: Rwanda | F18: 3
A19: Brazil | B19: 3 | C19: Jamaica | D19: 4 | E19: Saint Lucia | F19: 5
A20: Brunei | B20: 3 | C20: Japan | D20: 5 | E20: Saint Vincent | F20: 4
A21: Bulgaria | B21: 3 | C21: Jordan | D21: 6 | E21: Samoa | F21: 4
A22: Burkina Faso | B22: 3 | C22: Kazakhstan | D22: 3 | E22: Saudi Arabia | F22: 5
A23: Cambodia | B23: 3 | C23: Kenya | D23: 4 | E23: Senegal | F23: 4
A24: Cameroon | B24: 4 | C24: Korea Republic | D24: 5 | E24: Serbia | F24: 3
A25: Canada | B25: 5 | C25: Kosovo | D25: 2 | E25: Sierra Leone | F25: 2
A26: Chile | B26: 3 | C26: Kuwait | D26: 5 | E26: Singapore | F26: 6
A27: China | B27: 5 | C27: Kyrgyzstan | D27: 2 | E27: Slovakia | F27: 4
A28: Colombia | B28: 3 | C28: Laos | D28: 2 | E28: Slovenia | F28: 3
A29: Cook Islands | B29: 4 | C29: Latvia | D29: 4 | E29: Solomon Islands | F29: 4
... A49: Gambia | B49: 2 | C49: Nigeria | D49: 4 | E49: Vietnam | F49: 3

Sheet 6. Flights & Int Accommodation
A1: The ARC has advised that flight and accommodation costs should reflect prices at the time of application.
